Workbook

Sheet Start Here
A1: B2B Growth Content Intelligence: Outlier Research Workbook
A2: Built 17 Oct 2026 from Eden (LinkedIn, X, Instagram index) and vidIQ (Instagram Reels outliers). Accounts with 5k-100k followers, last 6-12 months, English + Hindi/Hinglish.
A4: How to use this workbook
A5: 1. ICP & Positioning | B5: Read first. Sharpened ICP, the assumptions I disagree with, and the reasoning. Decide before you write anything.
A6: 2. Strategy & Funnel | B6: Pillars, platform roles, funnel math, cadence and KPIs, grounded in the outlier data.
A7: 3. Master Database | B7: Every relevant post (ICP fit ≥3/10). Filter by Platform, Cluster, Signal, Hook Archetype, Offer. Sort by Priority Score. Use the Status column to track what you have reverse-engineered.
A8: 4. Top 30 Teardowns | B8: Hand-written analysis of the 30 most useful posts: why each worked and the exact adaptation for your offers.
A9: 5. Hidden Gems | B9: Accounts ≤30k followers whose post did ≥5x their own baseline. Idea beat audience, which is the most transferable signal for a new account.
A10: 6. Reels Teardown | B10: vidIQ Instagram outliers with 0-3s hook (visual, text, audio), format template, pacing, editing effort.
A11: 7. Hook Library | B11: Hook archetypes ranked by performance per platform, with fill-in templates for your niche.
A12: 8. Creator Watchlist | B12: Creators to study and engage with (comment-to-pipeline). Ranked by repeat outlier performance.
A13: 9. Cluster x Platform | B13: Live COUNTIFS/AVERAGEIFS pivot on the Master Database. Shows where each topic over-performs.
A14: 10. 30-Day Calendar | B14: 52 ready-to-write slots across LinkedIn, X and IG, each linked to a reference post. Change the start date (yellow cell) to re-date it.
A15: 11. India & Hindi | B15: What the Hindi/Hinglish data says, and why it changes your India plan.
A16: 12. Carousel Formula | B16: Design recipe from Eden study of top B2B client-acquisition carousels.
... A18: 14. Methodology | B18: Sources, queries, filters, definitions, caveats. Read before quoting any number.
A20: Signal definitions
A21: Outlier score | B21: Post performance ÷ that creator's own median (Eden: engagement-based; vidIQ: views ÷ median views). 10x = 10 times their normal post.
A22: Breakout | B22: Outlier ≥10x.
A23: Hidden Gem | B23: Creator ≤30k followers AND outlier ≥5x. Highest priority label when multiple apply.
A24: Viral | B24: ≥500k views, or ≥1k likes on LinkedIn, or ≥2k likes on X (absolute reach).
A25: Outlier | B25: 2-10x. Above baseline, not a breakout.
A26: ICP Fit (1-10) | B26: Model-assigned: topic keyword match to your 9 clusters, minus penalties for off-niche, AI-tool hype, aspirant/side-hustle audiences, and accounts outside 5k-100k. Directional, not gospel.
A28: Priority Score weights (editable inputs)
A29: Weight: ICP Fit | B29: 0.5
A30: Weight: Outlier (capped 50x, ÷5) | B30: 0.3
A31: Bonus: ≤30k followers | B31: 2
A32: Bonus: 30-60k followers | B32: 1
A33: Priority = W_fit × Fit + W_out × MIN(Outlier,50)/5 + small-account bonus. Blue/yellow cells are inputs: change them and every Priority Score in the Master Database recalculates.

Sheet ICP & Positioning
A1: ICP & Positioning: sharpened, with the assumptions I disagree with
A3: Assumptions I disagree with (read these first)
A4: #1 "Boutique firms, consultants, fractional execs" AND "10-50 employees" contradict each other | B4: Fractional executives and most independent consultants are 1-5 people, not 10-50. These are two different buyers with different budgets. A 1-3 person fractional practice ($300k-$1.5M revenue) cannot sustain a $6-10k/mo DFY retainer. A 25-person consultancy ($4-6M revenue) can. Pick the firm as the buyer. Treat solo fractionals as a referral channel, not a client.
A5: #2 "10-50 employees = has money" is only half true | B5: Professional-services revenue per employee is roughly $150-250k, so 10-50 staff is roughly $1.5M-$12M revenue. B2B firms spend about 3-8% of revenue on marketing. At $1.5M that is $45-120k/yr in total, so your retainer would eat the entire budget. At $4M it is $120-320k/yr, where a $90-120k/yr engagement fits. Real floor: about $3M revenue / 20+ staff. Qualify on revenue and founder-sourced-deal %, not headcount.
A6: #3 Two offers × two markets × three platforms × two languages is four businesses, not one | B6: One personal brand cannot credibly speak Hinglish cohort-pricing on Instagram and $10k/mo DFY on LinkedIn without diluting both. The data shows the winners in this research are mono-positioned (e.g. @nickavaria = agency numbers, @theroborourke = service-business sales). Fix: one system, two delivery modes (below).
A7: #4 Hindi-first content will not reach your Indian ICP | B7: I ran 5 dedicated Hindi/Hinglish pulls. At 5k-100k followers, Hindi business content is dominated by "earn in dollars", side hustles, numerology, retail/MSME tips and Raj Shamani clips (see "India & Hindi"). Almost nothing targets 10-50 person B2B service owners. Those owners read English on LinkedIn. Hindi is whitespace, but whitespace here mostly signals low buyer density, not an opportunity.
A8: #5 Virality is the wrong success metric for a content + warm-outbound offer | B8: For a firm selling $90k+/yr engagements, a post with 400 impressions that 6 target founders read beats one with 400k impressions from aspirants. Content's job is to (a) lift outbound reply rate, (b) give prospects proof when they check your profile, and (c) surface warm signals (who engages) to feed outbound. Use outliers to learn hooks and formats, not to chase reach.
A10: The reframe: one system, two delivery modes
A11: Core system (the thing you are known for) | B11: "Authority-to-Pipeline": founder-led content + signal-based warm outbound + a simple pipeline operating rhythm. Turns referral-dependent B2B firms into predictable new-logo machines.
A12: Delivery mode A: DFY (international, primary revenue) | B12: Done-for-you install + run for 10-50 person boutique B2B firms in US/UK/AU/CA/EU-English. $15-25k setup + $6-10k/mo, 6-month minimum. Target: 3-5 clients = $25-50k MRR.
A13: Delivery mode B: Cohort (India, cash flow + case studies) | B13: 6-8 week implementation cohort for Indian B2B service firms, prioritising EXPORT-ORIENTED firms (IT services, dev shops, B2B agencies, KPO/analytics) that want US/UK/ME clients. Same system, taught. ₹1-2.5L per firm (founder + 1 operator). 12-20 firms per cohort.
A14: Why this is sharper | B14: "International client hunting" stops being a separate topic and becomes the bridge. You teach Indian firms to win international clients using the exact system you run for international firms. Every DFY result becomes cohort curriculum; every cohort win becomes DFY social proof ("installed in 40+ firms"). One content engine feeds both.
A16: ICP A: Primary (DFY, international)
A17: Firmographics | B17: B2B professional-services firms, 15-50 staff, $3-12M revenue. US, UK, Canada, Australia, Netherlands/Nordics (English-fluent). Founder-led, not PE-owned.
A18: Sub-verticals (rank 1 to 5) | B18: 1) Boutique management/ops/RevOps consultancies 2) Specialist B2B agencies (demand gen, ABM, dev shops) 3) IT/cyber/compliance services 4) Advisory (M&A, fractional-exec collectives, finance) 5) Engineering/technical consultancies. Avoid: legal/medical (posting constraints), pure B2C agencies.
A19: Buyer | B19: Founder / Managing Partner / CEO. Still the #1 rainmaker. Influencer: Head of Growth or Ops if one exists.
A20: Trigger events (use as outbound signals) | B20: • >50% of new revenue from referrals or founder network • Lost or about to lose a top-3 client (concentration risk) • Hired a salesperson who failed in <9 months • Founder starts posting on LinkedIn inconsistently • Raised prices or launched a new service line • Hiring for "Business Development" or "Marketing Manager" • Just crossed or stalled at $3M / $5M / $10M
A21: Painful status quo (their words) | B21: "Pipeline is feast or famine." "Everything still comes through me." "We're the best-kept secret in our niche." "We tried an agency, got junk leads." "I don't have time to post."
A22: Expensive problem (quantified) | B22: A 25-person firm at $5M with 30% annual client churn must replace about $1.5M/yr of revenue. If the founder closes 70% of deals, that founder's time IS the growth ceiling. One extra $150k/yr client = 1.25x to 2x a $90-120k engagement. The ROI story is new logos, not leads.
A23: Disqualifiers | B23: <$2M revenue; no case studies/clients willing to be named; founder unwilling to be the face (content is founder-led); expects leads in 30 days; >100 staff with in-house marketing.
A25: ICP B: Secondary (India cohort)
A26: Firmographics | B26: Indian B2B service firms, 10-50 staff, ₹5-60 Cr revenue. Priority: firms selling or wanting to sell to international clients (IT services, SaaS dev, design/marketing agencies, data/analytics, KPO). Secondary: domestic B2B services.
A27: Core pains | B27: Dependent on Upwork/Clutch/referrals; competing on price; founder does all sales; no outbound system; LinkedIn profiles that read like CVs; can't articulate an expensive problem (see post: India-based design agency, 40x outlier).
A28: Language/platform reality | B28: English on LinkedIn (where they buy). Hinglish on IG reels for warmth and reach. Hindi only for selective clips. Do not build a Hindi-first channel.
A29: Offer and price logic | B29: Cohort ₹1-2.5L/firm. Outcome-based: "Installed: ICP + offer + 4 profiles + 30 posts + 2 outbound sequences + pipeline cadence in 6 weeks". Optional done-with-you upgrade ₹50-75k/mo.
A31: ICP C: Channel partners (not clients)
A32: Fractional execs & solo consultants | B32: 1-5 people, $300k-$1.5M. They sit inside your ICP A firms. Content for them builds referrals. Offer: referral fee (10-15% of year 1) or white-label. Data: fractional-exec content had the lowest median outlier (7.4x), so do not make them a content pillar; treat them as a relationship play.
A34: Positioning statement (draft)
A35: For founder-led B2B firms with 15-50 people who are stuck relying on referrals, I install an Authority-to-Pipeline system (founder content + signal-based warm outbound + a weekly pipeline rhythm) that produces 8-15 qualified conversations a month without the founder writing every post or sending every DM. Unlike lead-gen agencies, we build on the founder's authority and warm signals, so meetings come pre-trusted.
A37: Profile one-liners (test 2 for 30 days each)
A38: A (outcome) | B38: I help 15-50 person B2B firms get off referral dependency: founder-led content + warm outbound that books 8-15 qualified calls/month.
A39: B (mechanism) | B39: Authority-to-Pipeline for boutique consultancies & agencies | Content that warms. Outbound that converts. | Installed in 6 weeks.

Sheet Strategy & Funnel
A1: Content Strategy & Funnel
A2: Numbers marked [data] come from this research (ICP-fit ≥4, n=303, anomalous baselines excluded; all multiples quoted here are MEDIANS, while the Hook Library and Cluster sheets show capped AVERAGES, so the two differ). Numbers marked [assumption] are planning inputs; replace them with your own as you collect data.
A4: What the data says (and what it does not)
A5: Topic heat [data] | B5: Median outlier by cluster: High-Ticket Sales 52x (n=29) > Freelancing & International Clients 46x (n=11, aspirant-heavy) > Business Growth & Scale 24x (n=63) > Agency Growth 24x (n=19) > Outbound 23x (n=29) > Marketing Strategy 20x (n=95) > Content Marketing 16x (n=26) > Client Acquisition 12x (n=15) > Consulting/Fractional 7x (n=16).
A6: Implication | B6: Lead with SALES and PIPELINE ECONOMICS, not "content strategy". "How to do content" is crowded and under-performs (16x). Talk about content only as the warm layer of the pipeline system.
A7: Account size [data] | B7: Median outlier by follower band: 10-20k = 44x, 20-30k = 32x, 5-10k = 20x, 30-50k = 19x, 50-100k = 11x. Small accounts break out more often relative to their baseline. The bar to "win" is idea quality, not audience. (Caveat: smaller accounts have lower baselines, so multiples inflate.)
A8: Hooks on LinkedIn [data] | B8: Contrarian/Myth-Bust 27x > Objection/Quote 19x > Result-led 17x > Build/Demo 16x > Story 10x > Prediction 6x. Plain text "post" format 22x vs image posts 13x. Prediction/trend posts under-perform on LinkedIn.
A9: Hooks on X [data] | B9: Contrarian 52x > Declarative one-liners 36x > Result-led 35x > Story 31x > How-to 16x. X rewards compressed opinion and numbers.
A10: Hooks on IG [data] | B10: Objection/Quote hooks 108x (n=4) and Insider/Secret 69x (n=5) lead. Result-led 36x. Comment-gate reels 19x but convert reach into DMs. IG favours "here is the exact script/line" formats.
A11: CTA [data] | B11: Comment-keyword to DM posts: 26x median vs 20x for pure-value posts. On IG, 13 of 94 fit-qualified outliers used a comment gate. Use comment-gates for lead magnets 1 in 4 posts, not every post.
A12: What the data cannot tell you | B12: Which posts generated pipeline. Outlier = engagement, not revenue. Engagers on viral sales posts are often aspirants. Your own engager analysis (who from ICP engaged) is the real KPI.
A14: Content pillars and mix
A15: P1 Pipeline Diagnosis (25%) | B15: Referral dependency, founder-led sales ceiling, concentration risk, why agencies fail. Problem-aware TOFU. Hooks: contrarian, objection, number-led. Ref: @kathleenslatterybooth 351x, @silgofak 27x, @theroborourke India agency 41x.
A16: P2 Warm Outbound Plays (20%) | B16: Signal-based DMs, comment-to-pipeline, 2-sentence DMs, follow-up scripts. MOFU how-to. Ref: @theroborourke DM post 48x, @fin465 YC playbook 30x, @magalidereu comment system.
A17: P3 High-Ticket Sales & Pricing (15%) | B17: Discovery lines, objections, proposal-to-close, pricing retainers. Highest-heat cluster (52x). Ref: @theroborourke two-extremes 46x, @writewithkush objection, @itsashleyboston follow-up 220x.
A18: P4 Proof & Build-in-Public (15%) | B18: Client ledgers, pipeline reports, teardowns of real outbound, monthly revenue/source split. BOFU. Ref: @theroborourke $93k month 32x, @harry-wilson LinkedIn DM ledger 20x, @michlieben $153k MRR 326x.
A19: P5 Authority Content System (15%) | B19: How founder content converts (not how to go viral): attribution, invisible buyers, LinkedIn vs YouTube lead quality. Ref: @theroborourke web designer 35x, @paolo_scales whale clients.
A20: P6 Scale Systems (10%) | B20: Founder out of loops, team advocacy, KPI dashboards, onboarding docs. Ref: @nickavaria dashboard 44-112x, @agencysupply.co onboarding 60x.
A21: Series: International Client Hunting | B21: Cross-pillar weekly series for the India cohort: how Indian firms win US/UK clients (positioning, pricing in USD, outbound to international ICPs). English on LinkedIn, Hinglish reel cut on IG.
A23: Platform roles and cadence
A24: LinkedIn: conversion + proof (60% of effort) | B24: Where ICP A and ICP B buy. 5 posts/week (3 text, 1 carousel/doc, 1 proof). 20 strategic comments/day on ICP and adjacent-creator posts (comment-to-pipeline). Featured section: lead magnet + case study.
A25: X: idea lab + operator network (25%) | B25: 1-2 short posts/day plus 1 thread/week. Test hooks here first; promote winners (top 20% by engagement rate) to LinkedIn 3-7 days later. Network with agency/consultancy operators (see Creator Watchlist: 15 X creators).
A26: Instagram: trust video + India cohort (15%) | B26: 3 reels/week: 1 English talking-head (script/line format), 1 screen-record (system/tool), 1 Hinglish India-cohort reel. Pin an "If we've never met" intro reel. Comment-gate the lead magnet.
A27: Time budget [assumption] | B27: ≈10 hrs/week: 4h writing (batch Mon), 1.5h filming (batch Tue, 6 reels/session), 3h engagement (30 min/day ×6), 1.5h review + repurposing.
A29: Funnel architecture
A30: TOFU: Attention | B30: Contrarian diagnosis posts, aphorisms, stories. Goal: profile visits from ICP. KPI: ICP-follower growth (not total followers), profile views.
A31: MOFU: Capture | B31: Lead magnet: "Pipeline Dependency Scorecard" (10 questions, scores referral %, founder-sourced %, concentration, cycle). Delivered via comment-keyword (LinkedIn/IG) and DM. KPI: scorecard completions/week.
A32: Warm signal capture | B32: Everyone who comments, completes the scorecard, or engages 2+ times goes into a warm list (CRM). Enrich: company size 15-50, revenue proxy. This is where content becomes outbound.
A33: Warm outbound | B33: Signal-triggered DM within 24h: reference their engagement/scorecard, one insight, one question. No pitch in message 1. 3-touch over 10 days. KPI: reply rate ≥15% (vs ~3-5% cold).
A34: BOFU: Convert | B34: 30-min "Pipeline Diagnostic" call leading to a paid diagnostic ($1.5-2.5k, credited to setup) or a proposal. India: cohort application call or webinar.
A35: Proof loop | B35: Every client result becomes P4 content within 30 days; every objection heard becomes a P3 post.
A37: Funnel math: 6-month targets [assumption, replace with actuals]
A38: DFY goal | B38: 4 clients × $7.5k/mo = $30k MRR by month 6.
A39: Back-solve | B39: 4 clients ÷ 25% close = 16 qualified calls ÷ 80% show = 20 booked ÷ 30% positive-reply-to-call = 67 positive replies ÷ 15% warm reply rate ≈ 450 warm DMs ≈ 18/week. Content must generate ≥18 new warm ICP signals/week by month 3 (engagers + scorecard + profile viewers), topped up with signal-based outbound (hiring posts, funding, job changes).
A40: Cohort goal | B40: 15 firms × ₹1.5L = ₹22.5L per cohort. At 10% application-to-enrol: 150 applications. From scorecard/lead-magnet at 20% apply rate: 750 leads per cohort cycle (≈8 weeks), or about 95/week. Needs IG + LinkedIn reach, a webinar, and partner promotion. Realistically cohort 1 = 8-10 firms.
A41: Leading KPIs (weekly) | B41: ICP-qualified engagers, scorecard completions, warm DMs sent, reply rate, calls booked, and % of calls sourced from content signals.
A43: Sequencing (opportunity-cost view)
A44: Months 0-2 | B44: LinkedIn + X only. Build scorecard. 30 warm DMs/week from signals. Land 2 DFY pilots at a founder rate ($4-5k/mo) for case studies. Do NOT launch the cohort yet.
A45: Months 2-4 | B45: Add IG (3 reels/wk). Publish the first 2 case studies. Raise DFY to $7.5k+. Run a free 60-min "International Client Hunting" workshop for Indian firms to validate cohort demand (target 100+ registrations).
A46: Months 4-6 | B46: Launch cohort 1 if the workshop hits ≥100 registrations and ≥15 applications; otherwise sell done-with-you to the best 3 Indian firms instead.
...

Sheet Master Database
A1: # | B1: Platform | C1: Language | D1: Source | E1: Signal | F1: Breakout (≥10x) | G1: Hidden Gem | H1: Viral | I1: Primary Cluster | J1: Secondary Clusters | K1: Creator | L1: Handle | M1: Followers | N1: Follower Band | O1: Published | P1: URL | Q1: Hook (first line / title) | R1: Post Text (preview) | S1: Hook Archetype | T1: CTA Mechanism | U1: Funnel Stage | V1: Format | W1: Content Type | X1: Mood | Y1: Views | Z1: Likes | AA1: Comments | AB1: Shares | AC1: Engagement Rate | AD1: Outlier (raw) | AE1: Outlier (capped 100) | AF1: Creator Percentile | AG1: Anomalous Baseline? | AH1: ICP Fit (1-10) | AI1: AI-Tool Angle | AJ1: Aspirant Audience | AK1: Best-Fit Offer | AL1: Priority Score | AM1: Why It Worked | AN1: Reverse-Engineer Prompt | AO1: AI Summary | AP1: Topic Tags | AQ1: Found Via (query) | AR1: Status | AS1: My Adaptation Notes
A2: 1 | B2: X | C2: English | D2: Eden | E2: Hidden Gem | F2: Yes | G2: Yes | H2: No | I2: Marketing Strategy | J2: High-Ticket Sales, Outbound / Warm Outbound, Business Growth & Scale Systems | K2: MONTE | L2: @fromzerotomill | M2: 12888 | N2: 10-20k | O2: 2025-11-24 | P2: https://x.com/fromzerotomill/status/1992916088544256502 | Q2: i know a guy making $400k/yr selling "digital disappearance" guides to burned-out tech bros who want to delete their online presence | R2: i know a guy making $400k/yr selling "digital disappearance" guides to burned-out tech bros who want to delete their online presence instead of teaching people how to BUILD an online presence, this guy is teaching people how to DESTROY theirs and it's the smartest offer i've seen in years first, he understood who's buying this it's not paranoid preppers in bunkers it's: - 34 year old seni | S2: Story / Anecdote | T2: None (pure value) | U2: TOFU: Reach / POV | V2: text | W2: other | X2: informative | Y2: 105656 | Z2: 1016 | AA2: 36 | AB2: 67 | AC2: 0.010590974 | AD2: 243.68 | AE2: =IF(AD2="","",MIN(AD2,100)) -> 100 | AF2: 99 | AG2: No | AH2: 10 | AI2: No | AJ2: No | AK2: Intl: Authority-to-Pipeline DFY | AL2: =ROUND('Start Here'!$B$29*AH2+'Start Here'!$B$30*MIN(IF(AD2="",0,AD2),50)/5+IF(M2<=30000,'Start Here'!$B$31,IF(M2<=60000,'Start Here'!$B$32,0)),1) -> 10 | AM2: Small-account breakout: the idea beat the audience size; Specific number/result in the hook; First-person or observed story: narrative pull | AN2: Keep the story hook mechanic and swap in your own proof. Teach one marketing strategy lesson for founders of 10-50 person boutique firms (US/UK/AU). Ship it as a LinkedIn text/carousel. | AO2: A text post analyzes a high-income entrepreneur's $400k/year business offering guides for digital self-erasure to stressed tech professionals, detailing client demographics, market demand, and the multi-tiered pricing strategy that leverages referrals from affluent customers. | AP2: entrepreneurship, digital privacy, tech industry, business model, client acquisition, market demand, pricing strategy, cash flow | AQ2: referrals plateau service business founder stuck at revenue ceiling; premium pricing offer positioning charge more consulting retainer | AR2: Backlog
A3: 2 | B3: Instagram | C3: English | D3: Eden | E3: Hidden Gem | F3: Yes | G3: Yes | H3: No | I3: Marketing Strategy | J3: Agency Growth, High-Ticket Sales, Client Acquisition | K3: Meghan Clor • Marketing Agency | L3: @meghanclor | M3: 13612 | N3: 10-20k | O3: 2026-10-06 | P3: https://www.instagram.com/reel/DeKt5O_Sz9_/ | Q3: Attract clients who don’t flinch at your price 👀 | R3: Attract clients who don’t flinch at your price 👀 Love this clip from @prime.brains A small shift in messaging can completely change the type of buyer your offer attracts. This is one of my favorite ways to make marketing do more of the qualifying for you 🔥🧲 | S3: Statement / Declarative | T3: None (pure value) | U3: TOFU: Reach / POV | V3: short_video | W3: tutorial | X3: educational | Y3: 73913 | Z3: 2054 | AA3: 117 | AC3: 0.02937237 | AD3: 922.06 | AE3: =IF(AD3="","",MIN(AD3,100)) -> 100 | AF3: 98.6 | AG3: No | AH3: 10 | AI3: No | AJ3: No | AK3: Intl: Authority-to-Pipeline DFY | AL3: =ROUND('Start Here'!$B$29*AH3+'Start Here'!$B$30*MIN(IF(AD3="",0,AD3),50)/5+IF(M3<=30000,'Start Here'!$B$31,IF(M3<=60000,'Start Here'!$B$32,0)),1) -> 10 | AM3: Small-account breakout: the idea beat the audience size | AN3: Keep the statement hook mechanic and swap in your own proof. Teach one marketing strategy lesson for founders of 10-50 person boutique firms (US/UK/AU). Ship it as a IG reel, then repurpose to LinkedIn. | AO3: Marketing agency owner Meghan Clor shares a clip from @prime.brains explaining why words like "premium" and "luxury" don't sell, and how identity-based messaging attracts buyers who pay without flinching. Examples include a luxury travel offer rewritten for five-star travelers and the classic Rolls-Royce clock ad. | AP3: marketing, messaging, pricing, positioning, premium brand, luxury, client attraction, offer | AQ3: premium pricing offer positioning charge more consulting retainer | AR3: Backlog
A4: 3 | B4: Instagram | C4: English | D4: Eden | E4: Hidden Gem | F4: Yes | G4: Yes | H4: No | I4: Consulting / Fractional | J4: High-Ticket Sales, Marketing Strategy, Client Acquisition | K4: David Boland | L4: @justdavidboland | M4: 19437 | N4: 10-20k | O4: 2026-05-22 | P4: https://www.instagram.com/reel/DYo8Da5PPe3/ | Q4: Coaches and consultants: comment “chocolate” for the pricing masterclass for coaches & consultants where you’ll learn exactly how to pick a price for your offer and a plan to land a client in the next few hours (yes, it | R4: Coaches and consultants: comment “chocolate” for the pricing masterclass for coaches & consultants where you’ll learn exactly how to pick a price for your offer and a plan to land a client in the next few hours (yes, it is possible) | S4: Comment-Gate / Lead Magnet | T4: Comment keyword → DM | U4: Lead Capture (MOFU) | V4: text | W4: promo | X4: informative | Y4: 194374 | Z4: 7303 | AA4: 4823 | AC4: 0 | AD4: 410.07 | AE4: =IF(AD4="","",MIN(AD4,100)) -> 100 | AF4: 99.8 | AG4: No | AH4: 10 | AI4: No | AJ4: No | AK4: Intl: Authority-to-Pipeline DFY | AL4: =ROUND('Start Here'!$B$29*AH4+'Start Here'!$B$30*MIN(IF(AD4="",0,AD4),50)/5+IF(M4<=30000,'Start Here'!$B$31,IF(M4<=60000,'Start Here'!$B$32,0)),1) -> 10 | AM4: Small-account breakout: the idea beat the audience size; Comment-gate inflates comments, which the algorithm rewards | AN4: Keep the comment-gate hook mechanic and swap in your own proof. Teach one consulting / fractional lesson for founders of 10-50 person boutique firms (US/UK/AU). Ship it as a IG reel, then repurpose to LinkedIn. | AO4: This video instructs coaches and consultants on premium pricing and differentiation strategies by encouraging exclusive client engagement rather than mass affordability. Audience is instructed to comment 'chocolate' to receive the pricing masterclass. | AP4: pricing strategy, masterclass, exclusive clients, coaching, consulting, premium pricing, marketing | AQ4: premium pricing offer positioning charge more consulting retainer | AR4: Backlog
A5: 4 | B5: Instagram | C5: English | D5: Eden | E5: Hidden Gem | F5: Yes | G5: Yes | H5: No | I5: Marketing Strategy | J5: Consulting / Fractional, Client Acquisition, Outbound / Warm Outbound | K5: Chris Dufey | L5: @chrisdufey | M5: 5949 | N5: 5-10k | O5: 2026-10-05 | P5: https://www.instagram.com/reel/DeIN6T6zB0G/ | Q5: My 7 year old looked at me on the beach today, dead serious. | R5: My 7 year old looked at me on the beach today, dead serious. “Dad. Why aren’t you at work?” I am. (She didn’t buy it. She went back to burying her sister.) Most coaches can’t take half a day off without the whole business grinding to a halt. So you go to the beach “with the kids”. Your body’s on the sand. Your head’s in your phone, like a seagull guarding a chip. But you didn’t start this f | S5: Story / Anecdote | T5: None (pure value) | U5: TOFU: Reach / POV | V5: long_video | W5: promo | X5: aspirational | Y5: 10279 | Z5: 29 | AA5: 0 | AC5: 0.0028212861 | AD5: 161.76 | AE5: =IF(AD5="","",MIN(AD5,100)) -> 100 | AF5: 100 | AG5: No | AH5: 10 | AI5: No | AJ5: No | AK5: Intl: Authority-to-Pipeline DFY | AL5: =ROUND('Start Here'!$B$29*AH5+'Start Here'!$B$30*MIN(IF(AD5="",0,AD5),50)/5+IF(M5<=30000,'Start Here'!$B$31,IF(M5<=60000,'Start Here'!$B$32,0)),1) -> 10 | AM5: Small-account breakout: the idea beat the audience size; First-person or observed story: narrative pull | AN5: Keep the story hook mechanic and swap in your own proof. Teach one marketing strategy lesson for founders of 10-50 person boutique firms (US/UK/AU). Ship it as a IG reel, then repurpose to LinkedIn. | AO5: Chris Dufey tells a beach story about his daughter asking why he isn't at work to argue that coaches should build businesses that run without them. He promotes his team's done-for-you marketing and growth service and asks viewers with a proven offer to DM "TUESDAY" for a free demo call. | AP5: coaching business, client acquisition, time freedom, done-for-you marketing, demo call cta, freedom, business systems, lead generation | AQ5: client kaise laaye business grow kaise kare sales marketing agency | AR5: Backlog
A6: 5 | B6: Instagram | C6: English | D6: Eden | E6: Hidden Gem | F6: Yes | G6: Yes | H6: No | I6: Marketing Strategy | J6: Consulting / Fractional, Business Growth & Scale Systems, Client Acquisition | K6: Ollie Carson | Business Growth Coach | L6: @olliecarson__ | M6: 29450 | N6: 20-30k | O6: 2026-04-10 | P6: https://www.instagram.com/reel/DW8TbCSDWOZ/ | Q6: �Comment “ROADMAP” and I’ll send you my full breakdown on building a coaching offer that actually sells. | R6: �Comment “ROADMAP” and I’ll send you my full breakdown on building a coaching offer that actually sells. If we’ve never spoken before: I’m Ollie. I run RemotePro. I help online coaches and consultants build and scale their businesses without sleazy tactics or the copy-paste strategies that everyone else is selling. I’m the founder of RemotePro - a hands-on one-to-one mentorship program where y | S6: Comment-Gate / Lead Magnet | T6: Comment keyword → DM | U6: Lead Capture (MOFU) | V6: long_video | W6: tutorial | X6: educational | Y6: 120649 | Z6: 3013 | AA6: 3411 | AC6: 0.053245365 | AD6: 62.28 | AE6: =IF(AD6="","",MIN(AD6,100)) -> 62.28 | AF6: 99.7 | AG6: No | AH6: 10 | AI6: No | AJ6: No | AK6: Intl: Authority-to-Pipeline DFY | AL6: =ROUND('Start Here'!$B$29*AH6+'Start Here'!$B$30*MIN(IF(AD6="",0,AD6),50)/5+IF(M6<=30000,'Start Here'!$B$31,IF(M6<=60000,'Start Here'!$B$32,0)),1) -> 10 | AM6: Comment-gate inflates comments, which the algorithm rewards | AN6: Keep the comment-gate hook mechanic and swap in your own proof. Teach one marketing strategy lesson for founders of 10-50 person boutique firms (US/UK/AU). Ship it as a IG reel, then repurpose to LinkedIn. | AO6: A person explains a business funnel diagram on Instagram and Manychat for coaching, highlighting strategies for building and scaling coaching businesses with lead capture, personal branding, and social proof. Examples of client success are mentioned. | AP6: coaching business, business funnel, lead capture, personal brand, social proof, instagram marketing, manychat, client retention | AQ6: founder dependency hiring delegation scaling agency beyond the founder | AR6: Backlog
A7: 6 | B7: X | C7: English | D7: Eden | E7: Hidden Gem | F7: Yes | G7: Yes | H7: Yes | I7: Outbound / Warm Outbound | J7: Marketing Strategy, Client Acquisition, High-Ticket Sales | K7: Rob O'Rourke | L7: @theroborourke | M7: 10660 | N7: 10-20k | O7: 2025-11-17 | P7: https://x.com/theroborourke/status/1990343987148775791 | Q7: I work with a few guys doing anywhere from $50k/m to $400k/m using mostly cold outreach. | R7: I work with a few guys doing anywhere from $50k/m to $400k/m using mostly cold outreach. Here's what kills response rates... Messages that look like copy-paste essays. If your first DM is 6+ sentences in one huge block, you're done. Social media isn't email. People scan, they don't read. - You need to break your pitch into 2-3 short messages - Lead with the single most relevant thing about wh | S7: Story / Anecdote | T7: DM ask | U7: TOFU: Reach / POV | V7: text | W7: tutorial | X7: informative | Y7: 822907 | Z7: 1554 | AA7: 46 | AB7: 77 | AC7: 0.0020378974 | AD7: 48 | AE7: =IF(AD7="","",MIN(AD7,100)) -> 48 | AF7: 99.7 | AG7: No | AH7: 10 | AI7: No | AJ7: No | AK7: Intl: Authority-to-Pipeline DFY | AL7: =ROUND('Start Here'!$B$29*AH7+'Start Here'!$B$30*MIN(IF(AD7="",0,AD7),50)/5+IF(M7<=30000,'Start Here'!$B$31,IF(M7<=60000,'Start Here'!$B$32,0)),1) -> 9.9 | AM7: Authority by proximity ('I work with guys doing $50k-$400k/m') plus one concrete, checkable mistake (6+ sentence DMs). Instant self-audit for the reader. | AN7: 'I reviewed 214 LinkedIn DMs our clients' prospects actually replied to. The 3 that booked calls were all under 40 words.' Use your own outbound data. Attach a before/after DM screenshot. | AO7: The post advises sales professionals on improving cold outreach response rates by avoiding long, essay-like messages and instead using brief, conversational messages that lead with relevant points and proof. The author emphasizes getting initial replies before attempting to close deals. | AP7: cold outreach, sales advice, response rates, communication, dm strategy, sales tips, social media, email alternative | AQ7: LinkedIn DM outreach scripts and warm prospecting signals; cold email outbound that books meetings for consultants | AR7: Backlog
A8: 7 | B8: X | C8: English | D8: Eden | E8: Hidden Gem | F8: Yes | G8: Yes | H8: Yes | I8: Business Growth & Scale Systems | J8: Marketing Strategy, Outbound / Warm Outbound, Content Marketing & Systems | K8: Romàn | L8: @romanbuildsaas | M8: 22306 | N8: 20-30k | O8: 2026-04-24 | P8: https://x.com/romanbuildsaas/status/2047825608030494758 | Q8: Gojiberry AI just hit $2M ARR. | R8: Gojiberry AI just hit $2M ARR. A few months ago we were at €0. This is the second SaaS I've built. The first one I sold at €500K ARR. This time, we moved faster. Here's exactly how we did it, so you can do it too. The core principle that changed everything: We used our own tool to grow our own tool. Gojiberry AI finds high-intent leads and engages with them automatically. We run it on ourse | S8: Result / Number-Led Claim | T8: None (pure value) | U8: TOFU: Reach / POV | V8: image | W8: story | X8: inspirational | Y8: 528885 | Z8: 1769 | AA8: 341 | AB8: 212 | AC8: 0.0043903684 | AD8: 47.07 | AE8: =IF(AD8="","",MIN(AD8,100)) -> 47.07 | AF8: 99.5 | AG8: No | AH8: 10 | AI8: No | AJ8: No | AK8: Intl: Authority-to-Pipeline DFY | AL8: =ROUND('Start Here'!$B$29*AH8+'Start Here'!$B$30*MIN(IF(AD8="",0,AD8),50)/5+IF(M8<=30000,'Start Here'!$B$31,IF(M8<=60000,'Start Here'!$B$32,0)),1) -> 9.8 | AM8: Specific number/result in the hook; Proof-first opening | AN8: Keep the result hook mechanic and swap in your own proof. Teach one business growth & scale systems lesson for founders of 10-50 person boutique firms (US/UK/AU). Ship it as a LinkedIn text/carousel. | AO8: The author shares how his SaaS product reached $2M ARR after starting from zero, detailing growth tactics including outreach, inbound marketing, and AI automation, and discussing scaling challenges. | AP8: mrr milestones, saas, growth hacking, outreach, inbound marketing, reddit marketing, linkedin marketing, ai automation | AQ8: founder dependency hiring delegation scaling agency beyond the founder | AR8: Backlog
A9: 8 | B9: X | C9: English | D9: Eden | E9: Hidden Gem | F9: Yes | G9: Yes | H9: No | I9: High-Ticket Sales | J9: Business Growth & Scale Systems, Client Acquisition, Consulting / Fractional | K9: Nick Bennett | L9: @nickb2005 | M9: 5044 | N9: 5-10k | O9: 2026-09-02 | P9: https://x.com/NickB2005/status/2095121648710037913 | Q9: A client once asked me whether they should spend $40K on a sponsor booth at a major SaaS conference or try something smaller. | R9: A client once asked me whether they should spend $40K on a sponsor booth at a major SaaS conference or try something smaller. I told them to take $800, book a private dining room at a steakhouse 4 blocks away, and invite 8 target VPs of Operations who were already attending the event. We skipped the slide decks entirely. We ordered dry-aged ribeyes, poured two bottles of cabernet, and opened wit | S9: Story / Anecdote | T9: None (pure value) | U9: BOFU: Proof / Case Study | V9: text | W9: tutorial | X9: informative | Y9: 140419 | Z9: 1614 | AA9: 106 | AB9: 97 | AC9: 0.012939844 | AD9: 240.49 | AE9: =IF(AD9="","",MIN(AD9,100)) -> 100 | AF9: 99.8 | AG9: No | AH9: 9 | AI9: No | AJ9: No | AK9: Intl: Authority-to-Pipeline DFY | AL9: =ROUND('Start Here'!$B$29*AH9+'Start Here'!$B$30*MIN(IF(AD9="",0,AD9),50)/5+IF(M9<=30000,'Start Here'!$B$31,IF(M9<=60000,'Start Here'!$B$32,0)),1) -> 9.5 | AM9: Contrast in budget ($40K booth vs $800 dinner) + vivid detail + outcome. Small account (5k) at 240x: story quality beats audience size. | AN9: 'Skip the conference booth' play for boutique firms: 8-person founder dinner, then content recap, then warm outbound to attendees. Describe it as part of your system. | AO9: A consultant shares a case study about using a targeted dinner with key decision-makers instead of a large conference booth investment, resulting in significant closed deals and ARR from minimal spending. | AP9: saas, b2b, conference, client acquisition, sales strategy, dinner meeting, vp of operations, deal closing | AQ9: "fractional" CMO CFO COO getting clients | AR9: Backlog
A10: 9 | B10: X | C10: English | D10: Eden | E10: Hidden Gem | F10: Yes | G10: Yes | H10: No | I10: Business Growth & Scale Systems | J10: Outbound / Warm Outbound, Client Acquisition, Marketing Strategy | K10: Matthew Berman | L10: @themattberman | M10: 13338 | N10: 10-20k | O10: 2026-02-20 | P10: https://x.com/TheMattBerman/status/2024678503598235963 | Q10: I replaced a $200K GTM hire with @openclaw 😱 | R10: I replaced a $200K GTM hire with @openclaw 😱 here's the system that runs my outbound: step 1: mine LinkedIn engagement → @rapidapi scrapes everyone engaging with niche content → someone who commented on specific posts = 10x warmer step 2: enrich + verify → Hunter/Apollo finds the decision-maker + email → @Perplexity deep research pulls signals like hiring, fundraising, media appearances, quot | S10: Story / Anecdote | T10: None (pure value) | U10: TOFU: Reach / POV | V10: long_video | W10: tutorial | X10: educational | Y10: 188880 | Z10: 1905 | AA10: 1088 | AB10: 99 | AC10: 0.016370182 | AD10: 134.05 | AE10: =IF(AD10="","",MIN(AD10,100)) -> 100 | AF10: 98.8 | AG10: No | AH10: 8.6 | AI10: Yes | AJ10: No | AK10: Intl: Authority-to-Pipeline DFY | AL10: =ROUND('Start Here'!$B$29*AH10+'Start Here'!$B$30*MIN(IF(AD10="",0,AD10),50)/5+IF(M10<=30000,'Start Here'!$B$31,IF(M10<=60000,'Start Here'!$B$32,0)),1) -> 9.3 | AM10: Small-account breakout: the idea beat the audience size; Specific number/result in the hook; First-person or observed story: narrative pull; High comment-to-like ratio: debate driver | AN10: Keep the story hook mechanic and swap in your own proof. Teach one business growth & scale systems lesson for founders of 10-50 person boutique firms (US/UK/AU). Ship it as a LinkedIn text/carousel. | AO10: A LinkedIn video shows how the author automated his sales team's outbound lead generation process using various tools. The speaker outlines a six-step system for identifying, enriching, scoring, and reaching out to ideal customer profiles using API scraping, AI research, and personalized email sequences. | AP10: sales automation, outbound prospecting, ai tools, lead generation, marketing efficiency, workflow automation, cost savings, linked in engagement | AQ10: LinkedIn DM outreach scripts and warm prospecting signals | AR10: Backlog
A11: 10 | B11: X | C11: English | D11: Eden | E11: Hidden Gem | F11: Yes | G11: Yes | H11: Yes | I11: Freelancing & International Clients | J11: Consulting / Fractional, Client Acquisition, High-Ticket Sales | K11: Rob O'Rourke | L11: @theroborourke | M11: 10660 | N11: 10-20k | O11: 2025-11-17 | P11: https://x.com/theroborourke/status/1990376468736618997 | Q11: In my first year of freelancing, I went from selling $200 websites to $20k+ websites. | R11: In my first year of freelancing, I went from selling $200 websites to $20k+ websites. Here's a sales trick I used to figure out what clients actually wanted: Give two extreme options and see which way they lean. "Do you want to pause this idea completely and come back when timing is better, or do you want to try to get started on this in the next week or two?" This gets them to lean one way or | S11: Result / Number-Led Claim | T11: None (pure value) | U11: TOFU: Reach / POV | V11: text | W11: tutorial | X11: informative | Y11: 859734 | Z11: 1487 | AA11: 34 | AB11: 80 | AC11: 0.0018622039 | AD11: 45.94 | AE11: =IF(AD11="","",MIN(AD11,100)) -> 45.94 | AF11: 99.6 | AG11: No | AH11: 9 | AI11: No | AJ11: No | AK11: Intl: Authority-to-Pipeline DFY | AL11: =ROUND('Start Here'!$B$29*AH11+'Start Here'!$B$30*MIN(IF(AD11="",0,AD11),50)/5+IF(M11<=30000,'Start Here'!$B$31,IF(M11<=60000,'Start Here'!$B$32,0)),1) -> 9.3 | AM11: Transformation range ($200 to $20k) plus ONE usable sales line (two-extremes question). Low effort to apply, high save rate. | AN11: Series: 'One line I use on discovery calls with $5M consultancies' (e.g., 'If nothing changes in your pipeline for 6 months, what breaks first?'). One line per post, explain the psychology. | AO11: A freelancer shares a sales technique used to determine client intent by offering two extreme options, allowing them to either commit or respectfully decline the proposal. | AP11: freelancing, sales, client acquisition, pricing, web design, consulting | AQ11: freelancer to agency first clients Upwork pricing in dollars Hinglish | AR11: Backlog
A12: 11 | B12: LinkedIn | C12: English | D12: Eden | E12: Hidden Gem | F12: Yes | G12: Yes | H12: No | I12: Agency Growth | J12: Business Growth & Scale Systems, High-Ticket Sales, Marketing Strategy | K12: Nick Avaria | L12: @nickavaria | M12: 18671 | N12: 10-20k | O12: 2026-01-29 | P12: https://www.linkedin.com/feed/update/urn:li:activity:7422654796735807491 | Q12: I scaled my agency to $10M/yr in 3.5 years. | R12: I scaled my agency to $10M/yr in 3.5 years. Closing lots of deals didn’t get me there What did was a holistic understanding of my agency’s numbers and data. Which I used to make high-quality decisions that helped me grow fast. This KPI sheet makes managing your numbers easier. Agency founders, COOs, and heads of ops, this is for you if: - You have a “busy” team, but not a profitable one - | S12: Story / Anecdote | T12: None (pure value) | U12: TOFU: Reach / POV | V12: post | Z12: 214 | AA12: 543 | AB12: 1 | AC12: 0.041855329 | AD12: 43.7 | AE12: =IF(AD12="","",MIN(AD12,100)) -> 43.7 | AF12: 98.6 | AG12: No | AH12: 9 | AI12: No | AJ12: No | AK12: Intl: Authority-to-Pipeline DFY | AL12: =ROUND('Start Here'!$B$29*AH12+'Start Here'!$B$30*MIN(IF(AD12="",0,AD12),50)/5+IF(M12<=30000,'Start Here'!$B$31,IF(M12<=60000,'Start Here'!$B$32,0)),1) -> 9.1 | AM12: Big credible result ($10M agency) + reframe (not closing, numbers) + free KPI sheet. LinkedIn rewards resource posts with a comment-gate. | AN12: Build a 'Pipeline Health Scorecard' for 10-50 person firms (referral %, founder-sourced %, sales cycle, win rate, content-sourced %). Gate it via comment. This is your core lead magnet. | AQ12: agency growth scaling service business revenue | AR12: Backlog
A13: 12 | B13: X | C13: English | D13: Eden | E13: Hidden Gem | F13: Yes | G13: Yes | H13: No | I13: Marketing Strategy | J13: Business Growth & Scale Systems, Client Acquisition, Content Marketing & Systems | K13: Rob O'Rourke | L13: @theroborourke | M13: 10660 | N13: 10-20k | O13: 2026-01-28 | P13: https://x.com/theroborourke/status/2016436919505146264 | Q13: Working with a web designer who 3x'd his revenue last year. | R13: Working with a web designer who 3x'd his revenue last year. Went from $40K to around $130K. Almost ALL of it came from content. Mainly LinkedIn and YouTube. Plus around 10-20% in referrals. But here's what's interesting... His YouTube videos get a ton of views. But nearly all his actual paying leads came through the LinkedIn side. Why? The YT content was all technical. How he builds sites, | S13: Result / Number-Led Claim | T13: None (pure value) | U13: BOFU: Proof / Case Study | V13: text | W13: story | X13: informative | Y13: 271671 | Z13: 1129 | AA13: 26 | AB13: 48 | AC13: 0.0044281502 | AD13: 34.88 | AE13: =IF(AD13="","",MIN(AD13,100)) -> 34.88 | AF13: 99.3 | AG13: No | AH13: 10 | AI13: No | AJ13: No | AK13: Intl: Authority-to-Pipeline DFY | AL13: =ROUND('Start Here'!$B$29*AH13+'Start Here'!$B$30*MIN(IF(AD13="",0,AD13),50)/5+IF(M13<=30000,'Start Here'!$B$31,IF(M13<=60000,'Start Here'!$B$32,0)),1) -> 9.1 | AM13: Case study with a counter-intuitive split: YouTube got views, LinkedIn got paying leads. Data-backed platform insight. | AN13: Directly validates your thesis. Post: 'Our client's reels got 40x the views of their LinkedIn posts. LinkedIn produced 11 of 12 closed deals. Here's why.' Use your own or a client's attribution data. | AO13: Apost about a web designer who 3x’d his revenue to $130K by focusing on content marketing. Most leads came from LinkedIn expert content rather than YouTube technical videos. | AP13: web design, revenue growth, content marketing, social media marketing, linkedina, youtube, digital marketing, lead generation | AQ13: agency growth scaling service business revenue; referrals plateau service business founder stuck at revenue ceiling | AR13: Backlog
A14: 13 | B14: Instagram | C14: English | D14: Eden | E14: Breakout | F14: Yes | G14: No | H14: Yes | I14: High-Ticket Sales | J14: Client Acquisition, Outbound / Warm Outbound, Marketing Strategy | K14: Ashley Boston | Content Strategy for Creatives | L14: @itsashleyboston | M14: 57809 | N14: 50-100k | O14: 2026-03-28 | P14: https://www.instagram.com/reel/DWb9bMukmwe/ | Q14: The follow up message that brought back a lead I thought was gone forever 👇🏼 | R14: The follow up message that brought back a lead I thought was gone forever 👇🏼 No “just checking in.” No “did you get a chance to think about it?” No desperation. Just this: “Hey [Name], I’ve been thinking about our conversation and I realized I never actually asked you the most important question. What would need to be true for you to feel completely confident moving forward? Is it the | S14: Statement / Declarative | T14: None (pure value) | U14: TOFU: Reach / POV | V14: short_video | W14: tutorial | X14: informative | Y14: 896099 | Z14: 9063 | AA14: 2296 | AC14: 0.012676055 | AD14: 219.64 | AE14: =IF(AD14="","",MIN(AD14,100)) -> 100 | AF14: 99.7 | AG14: No | AH14: 10 | AI14: No | AJ14: No | AK14: Intl: Authority-to-Pipeline DFY | AL14: =ROUND('Start Here'!$B$29*AH14+'Start Here'!$B$30*MIN(IF(AD14="",0,AD14),50)/5+IF(M14<=30000,'Start Here'!$B$31,IF(M14<=60000,'Start Here'!$B$32,0)),1) -> 9 | AM14: Swipeable script (exact follow-up text). Specific 'No just checking in' contrast; saves and shares drive reach. | AN14: 'The follow-up I send 9 days after a proposal goes quiet' with the exact text. Make it a recurring 'Script Saturday' format. | AO14: A short sales tutorial video teaches how to write an effective follow-up message to recover a lost lead. The message focuses on understanding the client's real objections and avoids pressuring them, using open-ended questions to invite discussion. | AP14: sales follow-up, lead recovery, client engagement, sales script, high-ticket clients, sales objection handling, client communication, sales strategy | AQ14: sales system CRM follow-up process for service business owners | AR14: Backlog
A15: 14 | B15: X | C15: English | D15: Eden | E15: Hidden Gem | F15: Yes | G15: Yes | H15: Yes | I15: Marketing Strategy | J15: Agency Growth, Client Acquisition, Content Marketing & Systems | K15: MONTE | L15: @fromzerotomill | M15: 12888 | N15: 10-20k | O15: 2026-01-26 | P15: https://x.com/fromzerotomill/status/2015743611237785804 | Q15: had coffee with a guy last thursday who sold his marketing agency for $6.3m and i'm still processing what he told me | R15: had coffee with a guy last thursday who sold his marketing agency for $6.3m and i'm still processing what he told me we were supposed to talk for 30 minutes. ended up being almost 3 hours because what he said completely flipped how i think about building businesses "clients weren't paying for strategy. they were paying for the fact that i could get their message seen by their exact audience fast | S15: Result / Number-Led Claim | T15: None (pure value) | U15: TOFU: Reach / POV | V15: text | W15: story | X15: informative | Y15: 338478 | Z15: 2170 | AA15: 55 | AB15: 155 | AC15: 0.0070314762 | AD15: 520.9 | AE15: =IF(AD15="","",MIN(AD15,100)) -> 100 | AF15: 100 | AG15: No | AH15: 8 | AI15: No | AJ15: No | AK15: Intl: Authority-to-Pipeline DFY | AL15: =ROUND('Start Here'!$B$29*AH15+'Start Here'!$B$30*MIN(IF(AD15="",0,AD15),50)/5+IF(M15<=30000,'Start Here'!$B$31,IF(M15<=60000,'Start Here'!$B$32,0)),1) -> 9 | AM15: Small-account breakout: the idea beat the audience size; Specific number/result in the hook; Proof-first opening | AN15: Keep the result hook mechanic and swap in your own proof. Teach one marketing strategy lesson for founders of 10-50 person boutique firms (US/UK/AU). Ship it as a LinkedIn text/carousel. | AO15: A thread recounts a conversation with an entrepreneur who sold his marketing agency for $6.3M. The discussion focuses on the value of deeply trusted relationships with micro-influencers for customer acquisition, rather than traditional marketing tactics or proprietary strategies. | AP15: marketing agency, influencer relationships, micro influencers, business strategy, network effects, client acquisition, business growth, marketing insights | AQ15: client kaise laaye business grow kaise kare sales marketing agency; agency owner lessons scaling to 7 figures clients retention | AR15: Backlog
A16: 15 | B16: X | C16: English | D16: Eden | E16: Hidden Gem | F16: Yes | G16: Yes | H16: Yes | I16: Business Growth & Scale Systems | J16: Marketing Strategy, Client Acquisition, Content Marketing & Systems | K16: Michel Lieben | L16: @michlieben | M16: 13265 | N16: 10-20k | O16: 2026-04-01 | P16: https://x.com/MichLieben/status/2039432665078923529 | Q16: We offered $5,000 to whichever employee got the most engagement on LinkedIn in a single quarter. | R16: We offered $5,000 to whichever employee got the most engagement on LinkedIn in a single quarter. $2,500 for second. $1,500 for third. Plus $500 for anyone who published 20+ times. The result: 24 employees published 581 posts in 85 days. 43,000+ reactions. 28,000+ comments. 34,000+ new followers. 27 new clients signed. $153,000 in new MRR. I remember one guy from our team had less than 1,000 f | S16: Story / Anecdote | T16: None (pure value) | U16: BOFU: Proof / Case Study | V16: text | W16: story | X16: informative | Y16: 439499 | Z16: 6122 | AA16: 125 | AB16: 258 | AC16: 0.014800944 | AD16: 326.09 | AE16: =IF(AD16="","",MIN(AD16,100)) -> 100 | AF16: 100 | AG16: No | AH16: 8 | AI16: No | AJ16: No | AK16: Intl: Authority-to-Pipeline DFY | AL16: =ROUND('Start Here'!$B$29*AH16+'Start Here'!$B$30*MIN(IF(AD16="",0,AD16),50)/5+IF(M16<=30000,'Start Here'!$B$31,IF(M16<=60000,'Start Here'!$B$32,0)),1) -> 9 | AM16: Hard numbers at every step (581 posts, 85 days, 27 clients, $153K MRR). Employee-advocacy proof that content drives revenue. | AN16: For 10-50 person firms, the team is a distribution asset. Post: 'A 30-person consultancy has 30 LinkedIn accounts and uses 1'. Upsell path: team advocacy as an add-on. | AO16: A company offered tiered monetary prizes for LinkedIn engagement among employees, resulting in 581 posts, 107,000+ interactions, 34k+ new followers and $153k monthly recurring revenue. The $15k prize pool generated significant ROI. | AP16: employee incentives, linkedin engagement, social media competition, content marketing, mrr growth, organic reach, team motivation, reward program | AQ16: LinkedIn content strategy that books sales calls for B2B service businesses | AR16: Backlog
A17: 16 | B17: X | C17: English | D17: Eden | E17: Breakout | F17: Yes | G17: No | H17: Yes | I17: Freelancing & International Clients | J17: Marketing Strategy, Agency Growth, Consulting / Fractional | K17: MarketingMax.com | L17: @marketingmax | M17: 57635 | N17: 50-100k | O17: 2026-02-05 | P17: https://x.com/MarketingMax/status/2019410776201506904 | Q17: Hired a big-time marketing agency for some brand identity work | R17: Hired a big-time marketing agency for some brand identity work Paid them $250,000 They outsourced it to a smaller agency for $100,000 Who in turn outsourced it to a marketing consultant for $25,000 But that consultant outsourced my project to a US-based freelancer for $10,000 Who then outsourced it to an overseas freelancer for $2,000 The freelancer hired someone on Fiverr for $100 to finish | S17: Statement / Declarative | T17: None (pure value) | U17: TOFU: Reach / POV | V17: tweet | Y17: 192934 | Z17: 2448 | AA17: 98 | AB17: 57 | AC17: 0.01349166 | AD17: 212.85 | AE17: =IF(AD17="","",MIN(AD17,100)) -> 100 | AF17: 99.8 | AG17: No | AH17: 10 | AI17: No | AJ17: No | AK17: Intl: Authority-to-Pipeline DFY | AL17: =ROUND('Start Here'!$B$29*AH17+'Start Here'!$B$30*MIN(IF(AD17="",0,AD17),50)/5+IF(M17<=30000,'Start Here'!$B$31,IF(M17<=60000,'Start Here'!$B$32,0)),1) -> 9 | AM17: Outsourcing-chain story ($250K down to $100 on Fiverr). Funny, cynical, very shareable; sparks debate. | AN17: Reframe for your ICP: 'Why your $15K/mo agency retainer is really 2 juniors and a template'. Positions you as founder-led and transparent. Use as a TOFU reach post. | AQ17: freelancer to agency first clients Upwork pricing in dollars Hinglish | AR17: Backlog
A18: 17 | B18: Instagram | C18: Hindi | D18: vidIQ | E18: Hidden Gem | F18: Yes | G18: Yes | H18: No | I18: Agency Growth | J18: Marketing Strategy, Client Acquisition, Freelancing & International Clients | K18: itsliftmedia | L18: @itsliftmedia | M18: 6300 | N18: 5-10k | O18: Apr-Oct 2026 | P18: https://www.instagram.com/reel/DcGk3BOI4_r/ | Q18: aaj 200 | R18: Digital Agency Day 9 #BusinessGrowth #businessowner #agency #marketingagency #instagram | S18: Result / Number-Led Claim | T18: None (pure value) | U18: TOFU: Reach / POV | V18: Reel: B-roll over voiceover | W18: Education | Y18: 21900 | AD18: 106.3 | AE18: =IF(AD18="","",MIN(AD18,100)) -> 100 | AG18: No | AH18: 8 | AI18: No | AJ18: No | AK18: India: Growth & Scale Cohort | AL18: =ROUND('Start Here'!$B$29*AH18+'Start Here'!$B$30*MIN(IF(AD18="",0,AD18),50)/5+IF(M18<=30000,'Start Here'!$B$31,IF(M18<=60000,'Start Here'!$B$32,0)),1) -> 9 | AM18: Small-account breakout: the idea beat the audience size; Proof-first opening; Format: voiceover narration over b-roll montage | AN18: Keep the result hook mechanic and swap in your own proof. Teach one agency growth lesson for Indian B2B service founders (10-50 staff). Ship it as a IG reel, then repurpose to LinkedIn. | AO18: A digital entrepreneur documents the 9th day of building his agency, explaining the challenge of client communication and offering a template pack as a lead magnet. | AP18: Business & Entrepreneurship | AQ18: Client acquisition (Hindi/India); International clients (India) | AR18: Backlog
A19: 18 | B19: Instagram | C19: English | D19: Eden | E19: Breakout | F19: Yes | G19: No | H19: No | I19: Business Growth & Scale Systems | J19: Agency Growth, Marketing Strategy, High-Ticket Sales | K19: Austin Schneider | L19: @theaustinschneider | M19: 46241 | N19: 30-50k | O19: 2026-09-02 | P19: https://www.instagram.com/reel/Dcy173UgAVR/ | Q19: Follow @theaustinschneider for more | R19: Follow @theaustinschneider for more -- Hi, I'm Austin. I teach agency owners how to scale inside @agencyu.co. 7 years ago I started running my own agency. The advice out there? Grind harder, close more deals, just outwork everyone. It didn't work. I was doing $30K a month and still felt like I was drowning. So over the next few years I stopped following everyone else's playbook and built my own | S19: Statement / Declarative | T19: Follow ask | U19: TOFU: Reach / POV | V19: short_video | W19: tutorial | X19: inspirational | Y19: 85662 | Z19: 2055 | AA19: 81 | AC19: 0.02493521 | AD19: 48.12 | AE19: =IF(AD19="","",MIN(AD19,100)) -> 48.12 | AF19: 98.4 | AG19: No | AH19: 10 | AI19: No | AJ19: No | AK19: Intl: Authority-to-Pipeline DFY | AL19: =ROUND('Start Here'!$B$29*AH19+'Start Here'!$B$30*MIN(IF(AD19="",0,AD19),50)/5+IF(M19<=30000,'Start Here'!$B$31,IF(M19<=60000,'Start Here'!$B$32,0)),1) -> 8.9 | AM19: Origin story pinned as intro ('I was at $30K/mo and drowning'). Intro reels convert followers into buyers. | AN19: Record your own 60s 'If we've never met' reel: who you help, the one belief you reject, proof. Pin it on IG and feature it on LinkedIn. | AO19: Austin Schneider, an agency owner, shares his journey of building scalable systems that enabled his agency to grow from $30K to $200K+ per month. He promotes his program Agency U, which helps agency owners implement operational systems to scale without increased workload. | AP19: agency owners, business scaling, operational systems, client management, hiring systems, sales framework, lead generation, onboarding systems | AQ19: agency growth scaling service business revenue; client kaise laaye business grow kaise kare sales marketing agency | AR19: Backlog
A20: 19 | B20: X | C20: English | D20: Eden | E20: Hidden Gem | F20: Yes | G20: Yes | H20: Yes | I20: Outbound / Warm Outbound | J20: Marketing Strategy, Client Acquisition, Business Growth & Scale Systems | K20: Finn Mallery | L20: @fin465 | M20: 23968 | N20: 20-30k | O20: 2026-05-15 | P20: https://x.com/fin465/status/2055137077868814804 | Q20: talked to a bunch of current YC batch founders today | R20: talked to a bunch of current YC batch founders today The ones hitting $1m+ ARR (there are several this batch) are just ripping the same outbound playbook every time: 1. build your lead lists using tools like Origami or Clay 2. Run an auto-connect + DM sequencer on LinkedIn 3. aim for 200 connects/week. linkedin is a goldmine 4. when writing Linkedin DMs, send 2-sentences, ideally with a warm | S20: Statement / Declarative | T20: DM ask | U20: TOFU: Reach / POV | V20: text | W20: other | X20: informative | Y20: 356345 | Z20: 2994 | AA20: 76 | AB20: 129 | AC20: 0.0089772552 | AD20: 29.62 | AE20: =IF(AD20="","",MIN(AD20,100)) -> 29.62 | AF20: 94.5 | AG20: No | AH20: 10 | AI20: No | AJ20: No | AK20: Intl: Authority-to-Pipeline DFY | AL20: =ROUND('Start Here'!$B$29*AH20+'Start Here'!$B$30*MIN(IF(AD20="",0,AD20),50)/5+IF(M20<=30000,'Start Here'!$B$31,IF(M20<=60000,'Start Here'!$B$32,0)),1) -> 8.8 | AM20: Social proof by cohort (YC founders at $1M+ ARR) + numbered playbook with specifics (200 connects/week, 2-sentence DMs). | AN20: 'I looked at how 12 consultancies above $3M get new logos. 9 of them run this same 4-step warm outbound loop.' Follow with numbered steps. | AO20: A social media post by Finn Mallery details an outbound sales playbook used by Y Combinator founders who are achieving over $1M+ ARR. The playbook emphasizes LinkedIn strategies, including lead generation tools, automated connection requests, personalized DMs, frequent posting, and attention engine optimization (AEO) to consistently book demos. | AP20: linkedin marketing, b2b sales, outbound sales, lead generation, sales strategy, social selling, startup growth, demo booking | AQ20: LinkedIn DM outreach scripts and warm prospecting signals | AR20: Backlog
